Workbook

Sheet Formulas
B3: Performance Metrics | C3: Formulas
B4: Sensitivity (Recall) | C4: TPR = TP / (TP + FN)
B5: Specificity | C5: TNR = TN / (FP + TN)
B6: Positive Predictive Value (Precision) | C6: PPV = TP / (TP + FP)
B7: Negative Predictive Value | C7: NPV = TN / (TN + FN)
B8: Accuracy | C8: ACC = (TP + TN) / (P + N)
B9: F1 Score | C9: F1 score = (2 * PPV * TPR) / (PPV + TPR)
B10: MCC | C10: MCC = (TP * TN - FP * FN) / sqrt((TP + FP) * (TN + FN) * (FP + TN) * (TP + FN))
B11: Balanced Accuracy | C11: BACC = (TPR + SPC) / 2

Sheet LogRidge>

Sheet LogRidge
B2: Logistic Ridge Regression
B4: Confusion Matrix: Training Data* | G4: Variable | H4: Variable Label | I4: Caret (AUROC) | J4: Manual (AUPRC) | K4: Coefficients
B5: LR | C5: Reference Yes | D5: Reference No | G5: Cig9Rc | I5: 7.553645 | J5: 0.09378749 | K5: -0.06779842
B6: Predict Yes | C6: 15 | D6: 2 | G6: PRBQ18 | I6: 17.583289 | J6: 0.034369571 | K6: -0.13625722
B7: Predict No | C7: 21 | D7: 147 | G7: SCQ14 | I7: 9.039377 | J7: 0.0013615586 | K7: -0.0779395
G8: SCQ34 | I8: 8.098088 | J8: 0.0073891866 | K8: -0.07151459
B9: Training Performance | D9: *Model re-fit to full data. | G9: PRBQ2 | I9: 17.362313 | J9: 0.0004257173 | K9: -0.13474892
B10: Sensitivity | C10: 0.41667 | G10: PRBQ17 | I10: 13.144323 | J10: 0.0025862421 | K10: -0.10595841
B11: Specificity | C11: 0.98658 | G11: SCQ19 | I11: 5.944978 | J11: -0.0031936172 | K11: 0.05681823
B12: Precision (PPV) | C12: 0.88235 | G12: PRBQ1 | I12: 21.331087 | J12: 0.061626487 | K12: 0.16183837
B13: Negative Predictive Value (NPV) | C13: 0.875 | G13: PRBQ29 | I13: 15.72444 | J13: 0.025921113 | K13: -0.12356938
B14: Accuracy | C14: 0.8757 | G14: SCQ3 | I14: 4.324945 | J14: 0.0096343918 | K14: -0.04576045
B15: F-Score | C15: 0.566 | G15: PRBQ14 | I15: 0 | J15: 0.0027582193 | K15: 0.01623991
B16: MCC | C16: 0.5526 | G16: PRBQ23 | I16: 12.280368 | J16: 0.027478763 | K16: 0.10006136
B17: Balanced Accuracy | C17: 0.70162 | G17: Cig7 | J17: 0.027680262
G18: Cig7_X2 | I18: 54.153431 | K18: -0.38587208
B19: Confusion Matrix: Testing Data | G19: ContemplationStatus | J19: 0.083882397
B20: LR | C20: Reference Yes | D20: Reference No | G20: ContemplationStatus_X2 | I20: 20.555597 | K20: -0.15654515
B21: Predict Yes | C21: 1 | D21: 0 | G21: ContemplationStatus_X3 | I21: 100 | K21: 0.69880456
B22: Predict No | C22: 8 | D22: 37 | G22: ContemplationStatus_X4 | I22: 68.853576 | K22: 0.48621008
G23: ContemplationStatus_X5 | I23: 17.821058 | K23: 0.13788015
B24: Testing Performance | G24: EducationRc | J24: 0.049307131
B25: Sensitivity | C25: 0.1111 | G25: EducationRc_X2 | I25: 25.640343 | K25: -0.19125183
B26: Specificity | C26: 1 | G26: EducationRc_X3 | I26: 4.941232 | K26: 0.04996701
B27: Precision (PPV) | C27: 1 | G27: EducationRc_X4 | I27: 76.28267 | K27: -0.53691845
B28: Negative Predictive Value (NPV) | C28: 0.8222 | G28: EducationRc_X5 | I28: 32.953965 | K28: 0.24117202
B29: Accuracy | C29: 0.8261 | G29: EducationRc_X6 | I29: 28.817158 | K29: 0.21293564
B30: F-Score | C30: 0.2 | G30: SoC2BRc | J30: 0.022339448
B31: MCC | C31: 0.30225 | G31: SoC2BRc_X2 | I31: 69.580884 | K31: -0.49117443
B32: Balanced Accuracy | C32: 0.5556 | G32: SoC5BRc | J32: 0.0052151387
G33: SoC5BRc_X2 | I33: 10.059003 | K33: -0.0848991
B34: AUPRC by Repeated Resample | G34: SSEQ8BRc | J34: 0.035746495
B35: Resample | C35: AUPRC | E35: Hyperparameters | G35: SSEQ8BRc_X2 | I35: 24.9212 | K35: 0.18634321
B36: Rep1 | C36: 0.5706188 | E36: alpha = 0 | G36: SSEQ8BRc_X3 | I36: 18.27807 | K36: 0.14099955
B37: Rep2 | C37: 0.5196624 | E37: lambda = 0.1 | G37: SSEQ8BRc_X4 | I37: 42.200855 | K37: -0.30428803
B38: Rep3 | C38: 0.6051178 | G38: SSS17 | J38: 0.035478635
B39: Rep4 | C39: 0.5951438 | E39: lambda = c(seq(0.1, 10, by=0.1) | G39: SSS17_X1 | I39: 49.439606 | K39: -0.35369719
B40: Rep5 | C40: 0.6286141 | G40: SSEQ6BRc | J40: 0.006636394
G41: SSEQ6BRc_X2 | I41: 44.699823 | K41: 0.3213451
G42: SSEQ6BRc_X3 | I42: 24.995661 | K42: -0.18685145
...

Sheet LogRidge-W
B2: Logistic Ridge Regression
B4: Confusion Matrix: Training Data* | G4: Variable | H4: Variable Label | I4: Caret (AUROC) | J4: Manual (AUPRC) | K4: Coefficients
B5: LR | C5: Reference Yes | D5: Reference No | G5: Cig9Rc | I5: 8.418551 | J5: 0.043003467 | K5: -0.0044317144
B6: Predict Yes | C6: 28 | D6: 20 | G6: PRBQ18 | I6: 25.48674 | J6: 0.02215435 | K6: -0.012983124
B7: Predict No | C7: 8 | D7: 129 | G7: SCQ14 | I7: 14.26173 | J7: 0.022008211 | K7: -0.0073592314
G8: SCQ34 | I8: 14.860404 | J8: 0.0085242744 | K8: -0.007659176
B9: Training Performance | D9: *Model re-fit to full data. | G9: PRBQ2 | I9: 26.855142 | J9: -0.0003661402 | K9: -0.013668713
B10: Sensitivity | C10: 0.7778 | G10: PRBQ17 | I10: 22.71523 | J10: 0.014554265 | K10: -0.011594557
B11: Specificity | C11: 0.8658 | G11: SCQ19 | I11: 12.737817 | J11: -0.0056935574 | K11: 0.0065957291
B12: Precision (PPV) | C12: 0.5833 | G12: PRBQ1 | I12: 19.60618 | J12: 0.036276793 | K12: 0.010036878
B13: Negative Predictive Value (NPV) | C13: 0.9416 | G13: PRBQ29 | I13: 26.149452 | J13: 0.016015742 | K13: -0.013315152
B14: Accuracy | C14: 0.8486 | G14: SCQ3 | I14: 12.347033 | J14: 0.025126189 | K14: -0.0063999405
B15: F-Score | C15: 0.6667 | G15: PRBQ14 | I15: 15.09387 | J15: 0.0014098535 | K15: 0.0077761456
B16: MCC | C16: 0.5812 | G16: PRBQ23 | I16: 17.447938 | J16: 0.015273852 | K16: 0.0089555679
B17: Balanced Accuracy | C17: 0.8218 | G17: Cig7 | J17: 0.024576784
G18: Cig7_X2 | I18: 74.51964 | K18: -0.037549315
B19: Confusion Matrix: Testing Data | G19: ContemplationStatus | J19: 0.02442642
B20: LR | C20: Reference Yes | D20: Reference No | G20: ContemplationStatus_X2 | I20: 76.670381 | K20: -0.038626867
B21: Predict Yes | C21: 2 | D21: 6 | G21: ContemplationStatus_X3 | I21: 76.401975 | K21: 0.038492392
B22: Predict No | C22: 7 | D22: 31 | G22: ContemplationStatus_X4 | I22: 73.576017 | K22: 0.037076546
G23: ContemplationStatus_X5 | I23: 84.235269 | K23: 0.042416985
B24: Testing Performance | G24: EducationRc | J24: 0.035314047
B25: Sensitivity | C25: 0.22222 | G25: EducationRc_X2 | I25: 6.872444 | K25: -0.0036570923
B26: Specificity | C26: 0.83784 | G26: EducationRc_X3 | I26: 37.914931 | K26: 0.019209827
B27: Precision (PPV) | C27: 0.25 | G27: EducationRc_X4 | I27: 83.869838 | K27: -0.042233899
B28: Negative Predictive Value (NPV) | C28: 0.81579 | G28: EducationRc_X5 | I28: 15.486228 | K28: 0.0079727225
B29: Accuracy | C29: 0.7174 | G29: EducationRc_X6 | I29: 0 | K29: 0.0002138987
B30: F-Score | C30: 0.2353 | G30: SoC2BRc | J30: 0.020306752
B31: MCC | C31: 0.0629 | G31: SoC2BRc_X2 | I31: 100 | K31: -0.050315343
B32: Balanced Accuracy | C32: 0.53003 | G32: SoC5BRc | J32: 0.012686885
G33: SoC5BRc_X2 | I33: 73.977264 | K33: -0.037277576
B34: AUPRC by Repeated Resample | G34: SSEQ8BRc | J34: 0.042899226
B35: Resample | C35: AUPRC | E35: Hyperparameters | G35: SSEQ8BRc_X2 | I35: 49.393313 | K35: 0.024960662
B36: Rep1 | C36: 0.6031916 | E36: alpha = 0 | G36: SSEQ8BRc_X3 | I36: 38.199287 | K36: 0.019352294
B37: Rep2 | C37: 0.5541984 | E37: lambda = 5.8 | G37: SSEQ8BRc_X4 | I37: 65.117521 | K37: -0.032838717
B38: Rep3 | C38: 0.6279047 | G38: SSS17 | J38: 0.022808008
B39: Rep4 | C39: 0.6034478 | E39: lambda = c(seq(0.1, 10, by=0.1) | G39: SSS17_X1 | I39: 64.16645 | K39: -0.032362217
B40: Rep5 | C40: 0.6287879 | G40: SSEQ6BRc | J40: -0.012049715
G41: SSEQ6BRc_X2 | I41: 63.828018 | K41: 0.032192658
G42: SSEQ6BRc_X3 | I42: 39.217211 | K42: -0.019862288
...

Sheet LogRidge Data
B2: LogRidge
B4: Testing | C4: LogL2-W4 | D4: TPR | E4: =IF('LogRidge-W'!C25="","",'LogRidge-W'!C25) -> 0.22222
D5: TNR | E5: =IF('LogRidge-W'!C26="","",'LogRidge-W'!C26) -> 0.83784
D6: PPV | E6: =IF('LogRidge-W'!C27="","",'LogRidge-W'!C27) -> 0.25
D7: NPV | E7: =IF('LogRidge-W'!C28="","",'LogRidge-W'!C28) -> 0.81579
D8: ACC | E8: =IF('LogRidge-W'!C29="","",'LogRidge-W'!C29) -> 0.7174
D9: F1 | E9: =IF('LogRidge-W'!C30="","",'LogRidge-W'!C30) -> 0.2353
D10: MCC | E10: =IF('LogRidge-W'!C31="","",'LogRidge-W'!C31) -> 0.0629
D11: BACC | E11: =IF('LogRidge-W'!C32="","",'LogRidge-W'!C32) -> 0.53003
C12: LogL2 | D12: TPR | E12: =IF(LogRidge!C25="","",LogRidge!C25) -> 0.1111
D13: TNR | E13: =IF(LogRidge!C26="","",LogRidge!C26) -> 1
D14: PPV | E14: =IF(LogRidge!C27="","",LogRidge!C27) -> 1
D15: NPV | E15: =IF(LogRidge!C28="","",LogRidge!C28) -> 0.8222
D16: ACC | E16: =IF(LogRidge!C29="","",LogRidge!C29) -> 0.8261
D17: F1 | E17: =IF(LogRidge!C30="","",LogRidge!C30) -> 0.2
D18: MCC | E18: =IF(LogRidge!C31="","",LogRidge!C31) -> 0.30225
D19: BACC | E19: =IF(LogRidge!C32="","",LogRidge!C32) -> 0.5556
B20: Training | C20: LogL2-W4 | D20: TPR | E20: =IF('LogRidge-W'!C10="","",'LogRidge-W'!C10) -> 0.7778
D21: TNR | E21: =IF('LogRidge-W'!C11="","",'LogRidge-W'!C11) -> 0.8658
D22: PPV | E22: =IF('LogRidge-W'!C12="","",'LogRidge-W'!C12) -> 0.5833
D23: NPV | E23: =IF('LogRidge-W'!C13="","",'LogRidge-W'!C13) -> 0.9416
D24: ACC | E24: =IF('LogRidge-W'!C14="","",'LogRidge-W'!C14) -> 0.8486
D25: F1 | E25: =IF('LogRidge-W'!C15="","",'LogRidge-W'!C15) -> 0.6667
D26: MCC | E26: =IF('LogRidge-W'!C16="","",'LogRidge-W'!C16) -> 0.5812
D27: BACC | E27: =IF('LogRidge-W'!C17="","",'LogRidge-W'!C17) -> 0.8218
C28: LogL2 | D28: TPR | E28: =IF(LogRidge!C10="","",LogRidge!C10) -> 0.41667
D29: TNR | E29: =IF(LogRidge!C11="","",LogRidge!C11) -> 0.98658
D30: PPV | E30: =IF(LogRidge!C12="","",LogRidge!C12) -> 0.88235
D31: NPV | E31: =IF(LogRidge!C13="","",LogRidge!C13) -> 0.875
D32: ACC | E32: =IF(LogRidge!C14="","",LogRidge!C14) -> 0.8757
D33: F1 | E33: =IF(LogRidge!C15="","",LogRidge!C15) -> 0.566
D34: MCC | E34: =IF(LogRidge!C16="","",LogRidge!C16) -> 0.5526
D35: BACC | E35: =IF(LogRidge!C17="","",LogRidge!C17) -> 0.70162

Sheet SVM>

Sheet SVM Linear
B2: Support Vector Classifier: Linear Kernel
B4: Average Repeated 5-Fold Cross-Validation Training Performance | L4: Confusion Matrix: Training Data* | P4: Variable | Q4: Variable Label | R4: Caret (AUROC) | T4: Manual (AUPRC) | U4: Coefficients
B5: C | C5: AUPRC | D5: Precision | E5: Recall | F5: F | G5: AUPRC SD | H5: Precision SD | I5: Recall SD | J5: F SD | L5: SVM-L | M5: Reference Yes | N5: Reference No | R5: X1 | S5: X2
B6: 0.01 | C6: 0.4649203 | D6: 0.63 | E6: 0.35214286 | F6: 0.4532035 | G6: 0.09391532 | H6: 0.2141413 | I6: 0.19408231 | J6: 0.16688935 | L6: Predict Yes | M6: 15 | N6: 3 | P6: Cig9Rc | R6: 100 | S6: 100 | T6: 0.1899391 | U6: -0.16726256
B7: 0.1 | C7: 0.4601043 | D7: 0.75 | E7: 0.19928571 | F7: 0.3805648 | G7: 0.09304935 | H7: 0.3395258 | I7: 0.15418965 | J7: 0.1439052 | L7: Predict No | M7: 21 | N7: 146 | P7: PRBQ18 | R7: 62.447786 | S7: 62.447786 | T7: 0.022145714 | U7: -0.05394286
B8: 0.5 | C8: 0.4566795 | D8: 0.8222222 | E8: 0.12 | F8: 0.3367605 | G8: 0.08577846 | H8: 0.2985857 | I8: 0.12420239 | J8: 0.10972723 | P8: SCQ14 | R8: 70.634921 | S8: 70.634921 | T8: -0.00719945 | U8: -0.049173374
B9: 1 | C9: 0.4462118 | D9: 0.7692308 | E9: 0.105 | F9: 0.3284091 | G9: 0.09181427 | H9: 0.3212278 | I9: 0.13485 | J9: 0.12552108 | L9: Training Performance | N9: *Model re-fit to full data. | P9: SCQ34 | R9: 69.507101 | S9: 69.507101 | T9: 0.017453147 | U9: -0.050684414
B10: 2 | C10: 0.4450382 | D10: 0.71875 | E10: 0.06142857 | F10: 0.3890572 | G10: 0.0944877 | H10: 0.4519304 | I10: 0.12177821 | J10: 0.11780423 | L10: Sensitivity | M10: 0.41667 | P10: PRBQ2 | R10: 66.583124 | S10: 66.583124 | T10: 0.007492077 | U10: -0.027120528
B11: 3 | C11: 0.4434396 | D11: 0.8 | E11: 0.02714286 | F11: 0.2875 | G11: 0.09596338 | H11: 0.4472136 | I11: 0.06624013 | J11: 0.075 | L11: Specificity | M11: 0.97987 | P11: PRBQ17 | R11: 41.436926 | S11: 41.436926 | T11: 0.015644503 | U11: -0.064525657
B12: 4 | C12: 0.442335 | D12: 0.8 | E12: 0.02214286 | F12: 0.2430556 | G12: 0.09353226 | H12: 0.4472136 | I12: 0.051878 | J12: 0.01388889 | L12: Precision (PPV) | M12: 0.83333 | P12: SCQ19 | R12: 52.172097 | S12: 52.172097 | T12: 0.006828055 | U12: 0.035064317
B13: 5 | C13: 0.4415296 | D13: 0.9444444 | E13: 0.03928571 | F13: 0.2703704 | G13: 0.09491091 | H13: 0.1360828 | I13: 0.07645972 | J13: 0.06446998 | L13: Negative Predictive Value (NPV) | M13: 0.87425 | P13: PRBQ1 | R13: 53.592314 | S13: 53.592314 | T13: 0.035877452 | U13: 0.091466542
B14: 6 | C14: 0.4448877 | D14: 0.52 | E14: 0.03214286 | F14: 0.3853276 | G14: 0.09721204 | H14: 0.501996 | I14: 0.0950519 | J14: 0.11750842 | L14: Accuracy | M14: 0.8703 | P14: PRBQ29 | R14: 49.749373 | S14: 49.749373 | T14: 0.053909337 | U14: -0.091317214
B15: 7 | C15: 0.442795 | D15: 0.6666667 | E15: 0.02142857 | F15: 0.4222222 | G15: 0.09799238 | H15: 0.5773503 | I15: 0.07434521 | J15: 0.03142697 | L15: F-Score | M15: 0.5556 | P15: SCQ3 | R15: 49.081036 | S15: 49.081036 | T15: 0.002149725 | U15: -0.052360039
B16: 8 | C16: 0.4426805 | D16: 1 | E16: 0.01642857 | F16: 0.3333333 | G16: 0.09735955 | H16: 0 | I16: 0.06141057 | J16: 0.15713484 | L16: MCC | M16: 0.5297 | P16: PRBQ14 | R16: 40.643275 | S16: 40.643275 | T16: -0.001090655 | U16: 0.006587102
B17: 9 | C17: 0.4397249 | D17: 0.6666667 | E17: 0.02142857 | F17: 0.4222222 | G17: 0.09572644 | H17: 0.5773503 | I17: 0.07434521 | J17: 0.03142697 | L17: Balanced Accuracy | M17: 0.69827 | P17: PRBQ23 | R17: 41.645781 | S17: 41.645781 | T17: -0.003955964 | U17: 0.011574451
B18: 10 | C18: 0.4405684 | D18: 0.65 | E18: 0.03214286 | F18: 0.3853276 | G18: 0.09663081 | H18: 0.4725816 | I18: 0.0950519 | J18: 0.11750842 | P18: Cig7 | T18: 0.00816545
L19: Confusion Matrix: Testing Data | P19: Cig7_X2 | R19: 55.096074 | S19: 55.096074 | U19: -0.043418268
B20: Repeated 5-Fold Cross-Validation Training Performance for Best Hyperparameter(s) | H20: Hyperparameters | J20: Support Vectors | L20: SVM-L | M20: Reference Yes | N20: Reference No | P20: ContemplationStatus | T20: 0.037876047
B21: AUPRC | C21: Precision | D21: Recall | E21: F | F21: Resample | H21: C = 0.01 | J21: n = 82 | L21: Predict Yes | M21: 2 | N21: 0 | P21: ContemplationStatus_X2 | R21: 44.402673 | S21: 44.402673 | U21: -0.003729213
B22: 0.5156179 | C22: 1 | D22: 0.2857143 | E22: 0.4444444 | F22: Fold2.Rep4 | L22: Predict No | M22: 7 | N22: 37 | P22: ContemplationStatus_X3 | R22: 38.93066 | S22: 38.93066 | U22: 0.11577383
B23: 0.4375548 | C23: 0.5 | D23: 0.4285714 | E23: 0.4615385 | F23: Fold4.Rep3 | H23: AUPRC by Repeated Resample | P23: ContemplationStatus_X4 | R23: 24.519632 | S23: 24.519632 | U23: 0.057115016
B24: 0.439995 | C24: 0.6666667 | D24: 0.25 | E24: 0.3636364 | F24: Fold3.Rep5 | H24: Resample | I24: AUPRC | L24: Testing Performance | P24: ContemplationStatus_X5 | R24: 38.053467 | S24: 38.053467 | U24: 0.00852238
B25: 0.3224143 | C25: 0.25 | D25: 0.1428571 | E25: 0.1818182 | F25: Fold5.Rep4 | H25: Rep1 | I25: 0.554012 | L25: Sensitivity | M25: 0.22222 | P25: EducationRc | T25: 0.014039843
B26: 0.3947632 | C26: 0.6666667 | D26: 0.25 | E26: 0.3636364 | F26: Fold5.Rep1 | H26: Rep2 | I26: 0.4867172 | L26: Specificity | M26: 1 | P26: EducationRc_X2 | R26: 2.29741 | S26: 2.29741 | U26: -0.017383589
B27: 0.3366395 | C27: 0 | D27: 0 | E27: NaN | F27: Fold2.Rep1 | H27: Rep3 | I27: 0.5540197 | L27: Precision (PPV) | M27: 1 | P27: EducationRc_X3 | R27: 20.676692 | S27: 20.676692 | U27: 0.016664131
B28: 0.5566443 | C28: 0.8 | D28: 0.5 | E28: 0.6153846 | F28: Fold1.Rep3 | H28: Rep4 | I28: 0.5561275 | L28: Negative Predictive Value (NPV) | M28: 0.84091 | P28: EducationRc_X4 | R28: 34.544695 | S28: 34.544695 | U28: -0.098163036
B29: 0.3626607 | C29: 0.5 | D29: 0.4285714 | E29: 0.4615385 | F29: Fold3.Rep2 | H29: Rep5 | I29: 0.5903028 | L29: Accuracy | M29: 0.8478 | P29: EducationRc_X5 | R29: 3.258145 | S29: 3.258145 | U29: 0.014898648
B30: 0.5338212 | C30: 0.6666667 | D30: 0.2857143 | E30: 0.4 | F30: Fold1.Rep5 | L30: F-Score | M30: 0.3636 | P30: EducationRc_X6 | R30: 0 | S30: 0 | U30: 0.037260809
B31: 0.6094562 | C31: 0.5 | D31: 0.25 | E31: 0.3333333 | F31: Fold3.Rep4 | H31: Training Error* | J31: *From re-fit to full Training (i.e., not Tuning) | L31: MCC | M31: 0.4323 | P31: SoC2BRc | T31: 0.031366818
B32: 0.4714236 | C32: 0.8 | D32: 0.5714286 | E32: 0.6666667 | F32: Fold5.Rep3 | H32: 0.162162 | L32: Balanced Accuracy | M32: 0.61111 | P32: SoC2BRc_X2 | R32: 60.192147 | S32: 60.192147 | U32: -0.078321553
B33: 0.417122 | C33: 0.5 | D33: 0.2857143 | E33: 0.3636364 | F33: Fold4.Rep5 | P33: SoC5BRc | T33: -0.003773479
B34: 0.3933501 | C34: 0.6 | D34: 0.4285714 | E34: 0.5 | F34: Fold4.Rep2 | P34: SoC5BRc_X2 | R34: 54.845447 | S34: 54.845447 | U34: -0.013923263
B35: 0.4210599 | C35: 0.5 | D35: 0.125 | E35: 0.2 | F35: Fold1.Rep2 | P35: SSEQ8BRc | T35: -0.001001354
B36: 0.4486521 | C36: 0.6666667 | D36: 0.2857143 | E36: 0.4 | F36: Fold3.Rep1 | P36: SSEQ8BRc_X2 | R36: 33.375104 | S36: 33.375104 | U36: 0.021569305
B37: 0.39329 | C37: 0.5 | D37: 0.1428571 | E37: 0.2222222 | F37: Fold2.Rep3 | P37: SSEQ8BRc_X3 | R37: 15.288221 | S37: 15.288221 | U37: 0.012377215
B38: 0.6138425 | C38: 0.8 | D38: 0.5714286 | E38: 0.6666667 | F38: Fold5.Rep5 | P38: SSEQ8BRc_X4 | R38: 47.159566 | S38: 47.159566 | U38: -0.027213694
B39: 0.4622541 | C39: 0.6666667 | D39: 0.2857143 | E39: 0.4 | F39: Fold2.Rep5 | P39: SSS17 | T39: 0.046587354
B40: 0.4086899 | C40: 0.75 | D40: 0.4285714 | E40: 0.5454545 | F40: Fold4.Rep4 | P40: SSS17_X1 | R40: 47.577277 | S40: 47.577277 | U40: -0.075307146
B41: 0.492009 | C41: 1 | D41: 0.4285714 | E41: 0.6 | F41: Fold1.Rep4 | P41: SSEQ6BRc | T41: 0.019523579
B42: 0.4061547 | C42: 0.5 | D42: 0.1428571 | E42: 0.2222222 | F42: Fold3.Rep3 | P42: SSEQ6BRc_X2 | R42: 42.230576 | S42: 42.230576 | U42: 0.039401156
...

Sheet SVM Polynomial
B2: Support Vector Classifier: Polynomial Kernel
B4: Average Repeated 5-Fold Cross-Validation Training Performance | N4: Confusion Matrix: Training Data* | R4: Variable | S4: Variable Label | T4: Caret (AUROC) | V4: Manual (AUPRC)
B5: C | C5: degree | D5: scale | E5: AUPRC | F5: Precision | G5: Recall | H5: F | I5: AUPRC SD | J5: Precision SD | K5: Recall SD | L5: F SD | N5: SVM-P | O5: Reference Yes | P5: Reference No | T5: X1 | U5: X2
B6: 0.01 | C6: 2 | D6: 0.001 | E6: 0.4531474 | F6: 0.8 | G6: 0.02214286 | H6: 0.2430556 | I6: 0.09016713 | J6: 0.4472136 | K6: 0.051878 | L6: 0.01388889 | N6: Predict Yes | O6: 18 | P6: 2 | R6: Cig9Rc | T6: 100 | U6: 100 | V6: 0.062089619 | X6: Manual AUPRC value represents amount drop in AUPRC when variable is left out.
B7: 0.1 | C7: 2 | D7: 0.001 | E7: 0.468563 | F7: 0.6491429 | G7: 0.32285714 | H7: 0.4492298 | I7: 0.09515901 | J7: 0.27243 | K7: 0.16462827 | L7: 0.13709991 | N7: Predict No | O7: 18 | P7: 147 | R7: PRBQ18 | T7: 62.447786 | U7: 62.447786 | V7: 0.023341747
B8: 0.5 | C8: 2 | D8: 0.001 | E8: 0.4658969 | F8: 0.6659722 | G8: 0.33 | H8: 0.4539958 | I8: 0.09301894 | J8: 0.2498057 | K8: 0.18328018 | L8: 0.1670427 | R8: SCQ14 | T8: 70.634921 | U8: 70.634921 | V8: 0.010748082
B9: 1 | C9: 2 | D9: 0.001 | E9: 0.4680111 | F9: 0.6666667 | G9: 0.345 | H9: 0.4696878 | I9: 0.09403043 | J9: 0.2340052 | K9: 0.18113634 | L9: 0.14855319 | N9: Training Performance | P9: *Model re-fit to full data. | R9: SCQ34 | T9: 69.507101 | U9: 69.507101 | V9: 0.012917406
B10: 2 | C10: 2 | D10: 0.001 | E10: 0.4661291 | F10: 0.6245714 | G10: 0.30928571 | H10: 0.4460509 | I10: 0.09235866 | J10: 0.3052527 | K10: 0.18726743 | L10: 0.15788078 | N10: Sensitivity | O10: 0.5 | R10: PRBQ2 | T10: 66.583124 | U10: 66.583124 | V10: 0.011361878
B11: 3 | C11: 2 | D11: 0.001 | E11: 0.465754 | F11: 0.6373333 | G11: 0.335 | H11: 0.4626921 | I11: 0.09279263 | J11: 0.2631839 | K11: 0.16935125 | L11: 0.15304044 | N11: Specificity | O11: 0.9866 | R11: PRBQ17 | T11: 41.436926 | U11: 41.436926 | V11: -0.003015083
B12: 4 | C12: 2 | D12: 0.001 | E12: 0.4656532 | F12: 0.6429206 | G12: 0.31428571 | H12: 0.4355603 | I12: 0.0929233 | J12: 0.2836418 | K12: 0.16423071 | L12: 0.14568511 | N12: Precision (PPV) | O12: 0.9 | R12: SCQ19 | T12: 52.172097 | U12: 52.172097 | V12: 0.00163337
B13: 5 | C13: 2 | D13: 0.001 | E13: 0.4668706 | F13: 0.6525794 | G13: 0.37214286 | H13: 0.4935166 | I13: 0.09244515 | J13: 0.2292389 | K13: 0.20299365 | L13: 0.17243625 | N13: Negative Predictive Value (NPV) | O13: 0.8909 | R13: PRBQ1 | T13: 53.592314 | U13: 53.592314 | V13: 0.037519033
B14: 6 | C14: 2 | D14: 0.001 | E14: 0.4698104 | F14: 0.6204762 | G14: 0.33928571 | H14: 0.4553171 | I14: 0.09389326 | J14: 0.2612085 | K14: 0.19784393 | L14: 0.16724572 | N14: Accuracy | O14: 0.8919 | R14: PRBQ29 | T14: 49.749373 | U14: 49.749373 | V14: 0.038641696
B15: 7 | C15: 2 | D15: 0.001 | E15: 0.4681652 | F15: 0.6052381 | G15: 0.33357143 | H15: 0.4523298 | I15: 0.09512864 | J15: 0.2534839 | K15: 0.19361623 | L15: 0.16715169 | N15: F-Score | O15: 0.6429 | R15: SCQ3 | T15: 49.081036 | U15: 49.081036 | V15: 0.016577124
B16: 8 | C16: 2 | D16: 0.001 | E16: 0.4665583 | F16: 0.6603175 | G16: 0.32142857 | H16: 0.447058 | I16: 0.09811657 | J16: 0.2357709 | K16: 0.17655107 | L16: 0.15451966 | N16: MCC | O16: 0.6204 | R16: PRBQ14 | T16: 40.643275 | U16: 40.643275 | V16: 0.005513665
B17: 9 | C17: 2 | D17: 0.001 | E17: 0.4648458 | F17: 0.678373 | G17: 0.31642857 | H17: 0.4397419 | I17: 0.09669307 | J17: 0.2548165 | K17: 0.1983483 | L17: 0.16886416 | N17: Balanced Accuracy | O17: 0.7433 | R17: PRBQ23 | T17: 41.645781 | U17: 41.645781 | V17: 0.011859668
B18: 10 | C18: 2 | D18: 0.001 | E18: 0.4658422 | F18: 0.6666667 | G18: 0.305 | H18: 0.4375764 | I18: 0.09594929 | J18: 0.2552824 | K18: 0.15532635 | L18: 0.13896751 | R18: Cig7 | V18: 0.00849605
B19: 0.01 | C19: 2 | D19: 0.01 | E19: 0.4670646 | F19: 0.644381 | G19: 0.325 | H19: 0.4499056 | I19: 0.09235745 | J19: 0.2701068 | K19: 0.17042427 | L19: 0.14481678 | N19: Confusion Matrix: Testing Data | R19: Cig7_X2 | T19: 55.096074 | U19: 55.096074
B20: 0.1 | C20: 2 | D20: 0.01 | E20: 0.469029 | F20: 0.6441138 | G20: 0.35428571 | H20: 0.469308 | I20: 0.09471323 | J20: 0.2273029 | K20: 0.19996014 | L20: 0.16296173 | N20: SVM-P | O20: Reference Yes | P20: Reference No | R20: ContemplationStatus | V20: 0.072640893
B21: 0.5 | C21: 2 | D21: 0.01 | E21: 0.4704475 | F21: 0.6142381 | G21: 0.36642857 | H21: 0.4838147 | I21: 0.09658824 | J21: 0.2538369 | K21: 0.19480662 | L21: 0.16401868 | N21: Predict Yes | O21: 1 | P21: 0 | R21: ContemplationStatus_X2 | T21: 44.402673 | U21: 44.402673
B22: 1 | C22: 2 | D22: 0.01 | E22: 0.4681708 | F22: 0.702381 | G22: 0.32571429 | H22: 0.4497807 | I22: 0.10756567 | J22: 0.2857829 | K22: 0.20775515 | L22: 0.17583577 | N22: Predict No | O22: 8 | P22: 37 | R22: ContemplationStatus_X3 | T22: 38.93066 | U22: 38.93066
B23: 2 | C23: 2 | D23: 0.01 | E23: 0.4693683 | F23: 0.6611111 | G23: 0.27285714 | H23: 0.4574864 | I23: 0.104591 | J23: 0.3649388 | K23: 0.1917406 | L23: 0.15952821 | R23: ContemplationStatus_X4 | T23: 24.519632 | U23: 24.519632
B24: 3 | C24: 2 | D24: 0.01 | E24: 0.4578074 | F24: 0.757971 | G24: 0.275 | H24: 0.4008327 | I24: 0.09425462 | J24: 0.2167756 | K24: 0.16439243 | L24: 0.14506605 | N24: Testing Performance | R24: ContemplationStatus_X5 | T24: 38.053467 | U24: 38.053467
B25: 4 | C25: 2 | D25: 0.01 | E25: 0.4591157 | F25: 0.7819728 | G25: 0.23428571 | H25: 0.3870233 | I25: 0.09004881 | J25: 0.2362471 | K25: 0.14755303 | L25: 0.11529259 | N25: Sensitivity | O25: 0.1111 | R25: EducationRc | V25: 0.09489417
B26: 5 | C26: 2 | D26: 0.01 | E26: 0.4484292 | F26: 0.7263889 | G26: 0.23857143 | H26: 0.3704655 | I26: 0.08746035 | J26: 0.2792725 | K26: 0.11362813 | L26: 0.11046644 | N26: Specificity | O26: 1 | R26: EducationRc_X2 | T26: 2.29741 | U26: 2.29741
B27: 6 | C27: 2 | D27: 0.01 | E27: 0.4486015 | F27: 0.7401515 | G27: 0.25142857 | H27: 0.413888 | I27: 0.09125217 | J27: 0.2824055 | K27: 0.15795582 | L27: 0.13301075 | N27: Precision (PPV) | O27: 1 | R27: EducationRc_X3 | T27: 20.676692 | U27: 20.676692
B28: 7 | C28: 2 | D28: 0.01 | E28: 0.4490918 | F28: 0.6904762 | G28: 0.18285714 | H28: 0.3505582 | I28: 0.09206565 | J28: 0.3355581 | K28: 0.13621852 | L28: 0.1260339 | N28: Negative Predictive Value (NPV) | O28: 0.8222 | R28: EducationRc_X4 | T28: 34.544695 | U28: 34.544695
B29: 8 | C29: 2 | D29: 0.01 | E29: 0.436972 | F29: 0.6666667 | G29: 0.15571429 | H29: 0.3657828 | I29: 0.09199218 | J29: 0.3861642 | K29: 0.13516493 | L29: 0.10151013 | N29: Accuracy | O29: 0.8261 | R29: EducationRc_X5 | T29: 3.258145 | U29: 3.258145
B30: 9 | C30: 2 | D30: 0.01 | E30: 0.4338794 | F30: 0.75 | G30: 0.17785714 | H30: 0.3315618 | I30: 0.09371574 | J30: 0.3402069 | K30: 0.12799142 | L30: 0.11751722 | N30: F-Score | O30: 0.2 | R30: EducationRc_X6 | T30: 0 | U30: 0
B31: 10 | C31: 2 | D31: 0.01 | E31: 0.4312812 | F31: 0.6952381 | G31: 0.17357143 | H31: 0.3579966 | I31: 0.09187174 | J31: 0.356571 | K31: 0.13672867 | L31: 0.11445742 | N31: MCC | O31: 0.30225 | R31: SoC2BRc | V31: 0.01957163
B32: 0.01 | C32: 2 | D32: 0.1 | E32: 0.463135 | F32: 0.6649524 | G32: 0.38928571 | H32: 0.4938409 | I32: 0.1109653 | J32: 0.2361903 | K32: 0.17961007 | L32: 0.15572334 | N32: Balanced Accuracy | O32: 0.5556 | R32: SoC2BRc_X2 | T32: 60.192147 | U32: 60.192147
B33: 0.1 | C33: 2 | D33: 0.1 | E33: 0.441373 | F33: 0.6550794 | G33: 0.295 | H33: 0.4179006 | I33: 0.09652781 | J33: 0.299305 | K33: 0.16269611 | L33: 0.13259853 | R33: SoC5BRc | V33: 0.00395287
B34: 0.5 | C34: 2 | D34: 0.1 | E34: 0.3632566 | F34: 0.6166667 | G34: 0.18 | H34: 0.3142988 | I34: 0.09751253 | J34: 0.2935416 | K34: 0.11989136 | L34: 0.09868266 | N34: AUC by Repeated Resample | R34: SoC5BRc_X2 | T34: 54.845447 | U34: 54.845447
B35: 1 | C35: 2 | D35: 0.1 | E35: 0.360928 | F35: 0.6033333 | G35: 0.15714286 | H35: 0.3177048 | I35: 0.0924156 | J35: 0.3539088 | K35: 0.12489366 | L35: 0.12168487 | N35: Resample | O35: AUC | R35: SSEQ8BRc | V35: 0.074747364
B36: 2 | C36: 2 | D36: 0.1 | E36: 0.3611658 | F36: 0.5634921 | G36: 0.15714286 | H36: 0.3097363 | I36: 0.09302102 | J36: 0.3499452 | K36: 0.13152607 | L36: 0.11708779 | N36: Rep1 | O36: 0.4674107 | R36: SSEQ8BRc_X2 | T36: 33.375104 | U36: 33.375104
B37: 3 | C37: 2 | D37: 0.1 | E37: 0.3611658 | F37: 0.6055556 | G37: 0.16857143 | H37: 0.3009149 | I37: 0.09302102 | J37: 0.3196062 | K37: 0.11755915 | L37: 0.113933 | N37: Rep2 | O37: 0.4211819 | R37: SSEQ8BRc_X3 | T37: 15.288221 | U37: 15.288221
B38: 4 | C38: 2 | D38: 0.1 | E38: 0.3611658 | F38: 0.6214286 | G38: 0.18857143 | H38: 0.3503987 | I38: 0.09302102 | J38: 0.3319196 | K38: 0.13746134 | L38: 0.12259437 | N38: Rep3 | O38: 0.4715523 | R38: SSEQ8BRc_X4 | T38: 47.159566 | U38: 47.159566
B39: 5 | C39: 2 | D39: 0.1 | E39: 0.3611658 | F39: 0.5420635 | G39: 0.16214286 | H39: 0.3015806 | I39: 0.09302102 | J39: 0.3176135 | K39: 0.11911308 | L39: 0.10923208 | N39: Rep4 | O39: 0.4838939 | R39: SSS17 | V39: 0.033531792
B40: 6 | C40: 2 | D40: 0.1 | E40: 0.3611658 | F40: 0.594697 | G40: 0.17785714 | H40: 0.3184343 | I40: 0.09302102 | J40: 0.3574745 | K40: 0.11737818 | L40: 0.11446376 | N40: Rep5 | O40: 0.5013235 | R40: SSS17_X1 | T40: 47.577277 | U40: 47.577277
B41: 7 | C41: 2 | D41: 0.1 | E41: 0.3611658 | F41: 0.6380952 | G41: 0.18071429 | H41: 0.3309962 | I41: 0.09302102 | J41: 0.344486 | K41: 0.14073196 | L41: 0.12150985 | R41: SSEQ6BRc | V41: 0.065865511
B42: 8 | C42: 2 | D42: 0.1 | E42: 0.3611658 | F42: 0.615 | G42: 0.16285714 | H42: 0.3241863 | I42: 0.09302102 | J42: 0.3391984 | K42: 0.13396031 | L42: 0.12623112 | N42: Hyperparameters | P42: Support Vectors | R42: SSEQ6BRc_X2 | T42: 42.230576 | U42: 42.230576
...

Sheet SVM Radial
B2: Support Vector Classifier: Radial Kernel
B4: Average Repeated 5-Fold Cross-Validation Training Performance | M4: Confusion Matrix: Training Data* | Q4: Variable | R4: Variable Label | S4: Caret (AUROC) | U4: Manual (AUPRC)
B5: C | C5: sigma | D5: AUPRC | E5: Precision | F5: Recall | G5: F | H5: AUPRC SD | I5: Precision SD | J5: Recall SD | K5: F SD | M5: SVM-R | N5: Reference Yes | O5: Reference No | S5: X1 | T5: X2
B6: 0.01 | C6: 0.001 | D6: 0.4640411 | E6: 0.6666667 | F6: 0.01142857 | G6: 0.25 | H6: 0.10294445 | I6: 0.5773503 | J6: 0.03955535 | K6: 0 | M6: Predict Yes | N6: 15 | O6: 1 | Q6: Cig9Rc | S6: 100 | T6: 100 | U6: 0.11084287 | W6: Manual AUPRC value represents amount drop in AUPRC when variable is left out.
B7: 0.1 | C7: 0.001 | D7: 0.4664708 | E7: 0.6341905 | F7: 0.35357143 | G7: 0.4664413 | H7: 0.09759067 | I7: 0.2777723 | J7: 0.20077708 | K7: 0.16517358 | M7: Predict No | N7: 21 | O7: 148 | Q7: PRBQ18 | S7: 62.447786 | T7: 62.447786 | U7: 0.022371785
B8: 0.5 | C8: 0.001 | D8: 0.4691788 | E8: 0.6282857 | F8: 0.345 | G8: 0.4648448 | H8: 0.09337585 | I8: 0.2678918 | J8: 0.18113634 | K8: 0.14822958 | Q8: SCQ14 | S8: 70.634921 | T8: 70.634921 | U8: 0.0015966878
B9: 1 | C9: 0.001 | D9: 0.4689113 | E9: 0.6753333 | F9: 0.32071429 | G9: 0.4551412 | H9: 0.09342589 | I9: 0.2775188 | J9: 0.15859046 | K9: 0.14000555 | M9: Training Performance | O9: *Model re-fit to full data. | Q9: SCQ34 | S9: 69.507101 | T9: 69.507101 | U9: 0.018848895
B10: 2 | C10: 0.001 | D10: 0.4687436 | E10: 0.6309524 | F10: 0.32285714 | G10: 0.457713 | H10: 0.09362332 | I10: 0.2688776 | J10: 0.18869517 | K10: 0.15281008 | M10: Sensitivity | N10: 0.41667 | Q10: PRBQ2 | S10: 66.583124 | T10: 66.583124 | U10: 0.0053417851
B11: 3 | C11: 0.001 | D11: 0.4669468 | E11: 0.6538095 | F11: 0.31785714 | G11: 0.4228519 | H11: 0.09223109 | I11: 0.2319454 | J11: 0.16487665 | K11: 0.15084181 | M11: Specificity | N11: 0.99329 | Q11: PRBQ17 | S11: 41.436926 | T11: 41.436926 | U11: 0.0032763639
B12: 4 | C12: 0.001 | D12: 0.4671185 | E12: 0.602 | F12: 0.31785714 | G12: 0.4354829 | H12: 0.09261379 | I12: 0.2560075 | J12: 0.16995585 | K12: 0.14908166 | M12: Precision (PPV) | N12: 0.9375 | Q12: SCQ19 | S12: 52.172097 | T12: 52.172097 | U12: 0.0065380505
B13: 5 | C13: 0.001 | D13: 0.4668987 | E13: 0.6350476 | F13: 0.36071429 | G13: 0.4561219 | H13: 0.09227053 | I13: 0.2220746 | J13: 0.18363361 | K13: 0.15836864 | M13: Negative Predictive Value (NPV) | N13: 0.87574 | Q13: PRBQ1 | S13: 53.592314 | T13: 53.592314 | U13: 0.055248103
B14: 6 | C14: 0.001 | D14: 0.4696683 | E14: 0.6564762 | F14: 0.32357143 | G14: 0.4341524 | H14: 0.09380261 | I14: 0.2471068 | J14: 0.16098852 | K14: 0.15759627 | M14: Accuracy | N14: 0.8811 | Q14: PRBQ29 | S14: 49.749373 | T14: 49.749373 | U14: 0.043003838
B15: 7 | C15: 0.001 | D15: 0.4685881 | E15: 0.6393519 | F15: 0.35214286 | G15: 0.4659278 | H15: 0.09496929 | I15: 0.2316532 | J15: 0.20993348 | K15: 0.17429763 | M15: F-Score | N15: 0.5769 | Q15: SCQ3 | S15: 49.081036 | T15: 49.081036 | U15: 0.0029511894
B16: 8 | C16: 0.001 | D16: 0.4672559 | E16: 0.7038194 | F16: 0.33785714 | G16: 0.4593358 | H16: 0.09485321 | I16: 0.2588993 | J16: 0.20945193 | K16: 0.17570653 | M16: MCC | N16: 0.5774 | Q16: PRBQ14 | S16: 40.643275 | T16: 40.643275 | U16: 0.0003264166
B17: 9 | C17: 0.001 | D17: 0.4653772 | E17: 0.6971726 | F17: 0.35642857 | G17: 0.4745735 | H17: 0.09840458 | I17: 0.2405323 | J17: 0.22754606 | K17: 0.18607751 | M17: Balanced Accuracy | N17: 0.70498 | Q17: PRBQ23 | S17: 41.645781 | T17: 41.645781 | U17: -0.0019289155
B18: 10 | C18: 0.001 | D18: 0.4669442 | E18: 0.6558036 | F18: 0.28857143 | G18: 0.4264657 | H18: 0.09817124 | I18: 0.3021505 | J18: 0.18120674 | K18: 0.16480544 | Q18: Cig7 | U18: 0.0058824163
B19: 0.01 | C19: 0.01 | D19: 0.4629524 | E19: 0.6391429 | F19: 0.35214286 | G19: 0.4689489 | H19: 0.10732306 | I19: 0.2709487 | J19: 0.2120744 | K19: 0.17753268 | M19: Confusion Matrix: Testing Data | Q19: Cig7_X2 | S19: 55.096074 | T19: 55.096074
B20: 0.1 | C20: 0.01 | D20: 0.4670203 | E20: 0.6418095 | F20: 0.36857143 | G20: 0.4667883 | H20: 0.10725328 | I20: 0.2259617 | J20: 0.19924123 | K20: 0.17389575 | M20: SVM-R | N20: Reference Yes | O20: Reference No | Q20: ContemplationStatus | U20: 0.034740156
B21: 0.5 | C21: 0.01 | D21: 0.4652838 | E21: 0.6519669 | F21: 0.31785714 | G21: 0.4458716 | H21: 0.10904533 | I21: 0.2458799 | J21: 0.21632217 | K21: 0.17641793 | M21: Predict Yes | N21: 1 | O21: 0 | Q21: ContemplationStatus_X2 | S21: 44.402673 | T21: 44.402673
B22: 1 | C22: 0.01 | D22: 0.4660327 | E22: 0.6604167 | F22: 0.35714286 | G22: 0.4677258 | H22: 0.10877143 | I22: 0.2425614 | J22: 0.22769316 | K22: 0.18491374 | M22: Predict No | N22: 8 | O22: 37 | Q22: ContemplationStatus_X3 | S22: 38.93066 | T22: 38.93066
B23: 2 | C23: 0.01 | D23: 0.4718462 | E23: 0.708 | F23: 0.35428571 | G23: 0.4701555 | H23: 0.11109199 | I23: 0.2613675 | J23: 0.19484481 | K23: 0.17532416 | Q23: ContemplationStatus_X4 | S23: 24.519632 | T23: 24.519632
B24: 3 | C24: 0.01 | D24: 0.4640627 | E24: 0.7298611 | F24: 0.27214286 | G24: 0.4111077 | H24: 0.10528821 | I24: 0.2751363 | J24: 0.13175619 | K24: 0.12616706 | M24: Testing Performance | Q24: ContemplationStatus_X5 | S24: 38.053467 | T24: 38.053467
B25: 4 | C25: 0.01 | D25: 0.4613374 | E25: 0.7282609 | F25: 0.28714286 | G25: 0.437569 | H25: 0.1052507 | I25: 0.2660711 | J25: 0.16276143 | K25: 0.13541404 | M25: Sensitivity | N25: 0.1111 | Q25: EducationRc | U25: 0.0041664132
B26: 5 | C26: 0.01 | D26: 0.4600422 | E26: 0.707971 | F26: 0.28 | G26: 0.4529452 | H26: 0.09825627 | I26: 0.324032 | J26: 0.16184457 | K26: 0.13761643 | M26: Specificity | N26: 1 | Q26: EducationRc_X2 | S26: 2.29741 | T26: 2.29741
B27: 6 | C27: 0.01 | D27: 0.4548545 | E27: 0.7442857 | F27: 0.23642857 | G27: 0.3954337 | H27: 0.10008376 | I27: 0.2529553 | J27: 0.15940939 | K27: 0.12463237 | M27: Precision (PPV) | N27: 1 | Q27: EducationRc_X3 | S27: 20.676692 | T27: 20.676692
B28: 7 | C28: 0.01 | D28: 0.4484169 | E28: 0.6649123 | F28: 0.19428571 | G28: 0.3989556 | H28: 0.09704472 | I28: 0.3447084 | J28: 0.15866082 | K28: 0.12452535 | M28: Negative Predictive Value (NPV) | N28: 0.8222 | Q28: EducationRc_X4 | S28: 34.544695 | T28: 34.544695
B29: 8 | C29: 0.01 | D29: 0.4397621 | E29: 0.6873016 | F29: 0.19071429 | G29: 0.3631804 | H29: 0.09919403 | I29: 0.3266796 | J29: 0.13469227 | K29: 0.10361388 | M29: Accuracy | N29: 0.8261 | Q29: EducationRc_X5 | S29: 3.258145 | T29: 3.258145
B30: 9 | C30: 0.01 | D30: 0.4323235 | E30: 0.772807 | F30: 0.20642857 | G30: 0.4085146 | H30: 0.10574868 | I30: 0.2851906 | J30: 0.16187412 | K30: 0.11578087 | M30: F-Score | N30: 0.2 | Q30: EducationRc_X6 | S30: 0 | T30: 0
B31: 10 | C31: 0.01 | D31: 0.4232119 | E31: 0.7125 | F31: 0.17785714 | G31: 0.3656846 | H31: 0.10815103 | I31: 0.3601849 | J31: 0.13447112 | K31: 0.11971414 | M31: MCC | N31: 0.30225 | Q31: SoC2BRc | U31: 0.044074613
B32: 0.01 | C32: 0.1 | D32: 0.3757963 | E32: 0.6904762 | F32: 0.11142857 | G32: 0.3214064 | H32: 0.0813864 | I32: 0.3125382 | J32: 0.12524211 | K32: 0.11171639 | M32: Balanced Accuracy | N32: 0.5556 | Q32: SoC2BRc_X2 | S32: 60.192147 | T32: 60.192147
B33: 0.1 | C33: 0.1 | D33: 0.3757179 | E33: 0.5723923 | F33: 0.19642857 | G33: 0.361997 | H33: 0.08325671 | I33: 0.3243674 | J33: 0.15064346 | K33: 0.09782193 | Q33: SoC5BRc | U33: -0.0014520784
B34: 0.5 | C34: 0.1 | D34: 0.3758584 | E34: 0.5409091 | F34: 0.14571429 | G34: 0.3081471 | H34: 0.08325879 | I34: 0.3797704 | J34: 0.12249618 | K34: 0.09485217 | M34: AUC by Repeated Resample | Q34: SoC5BRc_X2 | S34: 54.845447 | T34: 54.845447
B35: 1 | C35: 0.1 | D35: 0.3765691 | E35: 0.5452381 | F35: 0.17714286 | G35: 0.3259171 | H35: 0.0827617 | I35: 0.2881523 | J35: 0.12509775 | K35: 0.10812932 | M35: Resample | N35: AUC | Q35: SSEQ8BRc | U35: -0.0039515685
B36: 2 | C36: 0.1 | D36: 0.3586648 | E36: 0.5141667 | F36: 0.13 | G36: 0.2892992 | H36: 0.07800646 | I36: 0.3549679 | J36: 0.11601647 | K36: 0.08249424 | M36: Rep1 | N36: 0.4040492 | Q36: SSEQ8BRc_X2 | S36: 33.375104 | T36: 33.375104
B37: 3 | C37: 0.1 | D37: 0.3580271 | E37: 0.4947368 | F37: 0.14571429 | G37: 0.3267314 | H37: 0.07922985 | I37: 0.3387091 | J37: 0.14767544 | K37: 0.11231306 | M37: Rep2 | N37: 0.3610237 | Q37: SSEQ8BRc_X3 | S37: 15.288221 | T37: 15.288221
B38: 4 | C38: 0.1 | D38: 0.3580271 | E38: 0.485 | F38: 0.15714286 | G38: 0.3141071 | H38: 0.07922985 | I38: 0.2884674 | J38: 0.13491699 | K38: 0.10547601 | M38: Rep3 | N38: 0.4162944 | Q38: SSEQ8BRc_X4 | S38: 47.159566 | T38: 47.159566
B39: 5 | C39: 0.1 | D39: 0.3580271 | E39: 0.5328947 | F39: 0.15142857 | G39: 0.3237374 | H39: 0.07922985 | I39: 0.3234468 | J39: 0.15030086 | K39: 0.12876404 | M39: Rep4 | N39: 0.4048893 | Q39: SSS17 | U39: 0.051546787
B40: 6 | C40: 0.1 | D40: 0.3580271 | E40: 0.5 | F40: 0.14571429 | G40: 0.3032977 | H40: 0.07922985 | I40: 0.2879652 | J40: 0.12925167 | K40: 0.11318768 | M40: Rep5 | N40: 0.4288902 | Q40: SSS17_X1 | S40: 47.577277 | T40: 47.577277
B41: 7 | C41: 0.1 | D41: 0.3580271 | E41: 0.4478836 | F41: 0.12857143 | G41: 0.2936219 | H41: 0.07922985 | I41: 0.2715955 | J41: 0.13172795 | K41: 0.10877567 | Q41: SSEQ6BRc | U41: 0.012080519
B42: 8 | C42: 0.1 | D42: 0.3580271 | E42: 0.5462185 | F42: 0.13428571 | G42: 0.2974026 | H42: 0.07922985 | I42: 0.2646596 | J42: 0.1222182 | K42: 0.10697449 | M42: Hyperparameters | O42: Support Vectors | Q42: SSEQ6BRc_X2 | S42: 42.230576 | T42: 42.230576
...

Sheet SVM Weighted Radial
B2: Support Vector Classifier: Radial Weight Kernel
B4: Average Repeated 5-Fold Cross-Validation Training Performance | N4: Confusion Matrix: Training Data* | R4: Variable | S4: Variable Label | T4: Caret (AUROC) | V4: Manual (AUPRC)
B5: C | C5: sigma | D5: weight | E5: AUPRC | F5: Precision | G5: Recall | H5: F | I5: AUPRC SD | J5: Precision SD | K5: Recall SD | L5: F SD | N5: SVM-WR | O5: Reference Yes | P5: Reference No | T5: X1 | U5: X2 | X5: Manual AUPRC value represents amount drop in AUPRC when variable is left out.
B6: 0.01 | C6: 0.001 | D6: 2 | E6: 0.4853108 | F6: NaN | G6: 0 | H6: NaN | I6: 0.09393888 | J6: NA | K6: 0 | L6: NA | N6: Predict Yes | O6: 29 | P6: 25 | R6: Cig9Rc | T6: 100 | U6: 100 | V6: 0.016882696
B7: 0.01 | C7: 0.001 | D7: 4 | E7: 0.2026174 | F7: NaN | G7: 0 | H7: NaN | I7: 0.18544763 | J7: NA | K7: 0 | L7: NA | N7: Predict No | O7: 7 | P7: 124 | R7: PRBQ18 | T7: 62.447786 | U7: 62.447786 | V7: 0.028706811
B8: 0.01 | C8: 0.001 | D8: 8 | E8: 0.4876052 | F8: 0.1945251 | G8: 1 | H8: 0.3256038 | I8: 0.09282795 | J8: 0.009014427 | K8: 0 | L8: 0.01250634 | R8: SCQ14 | T8: 70.634921 | U8: 70.634921 | V8: 0.028372719
B9: 0.1 | C9: 0.001 | D9: 2 | E9: 0.4890615 | F9: NaN | G9: 0 | H9: NaN | I9: 0.09170682 | J9: NA | K9: 0 | L9: NA | N9: Training Performance | P9: *Model re-fit to full data. | R9: SCQ34 | T9: 69.507101 | U9: 69.507101 | V9: -0.0023344253
B10: 0.1 | C10: 0.001 | D10: 4 | E10: 0.5142056 | F10: NaN | G10: 0 | H10: NaN | I10: 0.08131492 | J10: NA | K10: 0 | L10: NA | N10: Sensitivity | O10: 0.8056 | R10: PRBQ2 | T10: 66.583124 | U10: 66.583124 | V10: 0.013338468
B11: 0.1 | C11: 0.001 | D11: 8 | E11: 0.4909026 | F11: 0.1945251 | G11: 1 | H11: 0.3256038 | I11: 0.08831777 | J11: 0.009014427 | K11: 0 | L11: 0.01250634 | N11: Specificity | O11: 0.8322 | R11: PRBQ17 | T11: 41.436926 | U11: 41.436926 | V11: 0.0064277805
B12: 0.5 | C12: 0.001 | D12: 2 | E12: 0.4873275 | F12: NaN | G12: 0 | H12: NaN | I12: 0.09173223 | J12: NA | K12: 0 | L12: NA | N12: Precision (PPV) | O12: 0.537 | R12: SCQ19 | T12: 52.172097 | U12: 52.172097 | V12: 0.0088302775
B13: 0.5 | C13: 0.001 | D13: 4 | E13: 0.5114496 | F13: 0.5708425 | G13: 0.575 | H13: 0.553415 | I13: 0.08769237 | J13: 0.16707998 | K13: 0.17104682 | L13: 0.12311255 | N13: Negative Predictive Value (NPV) | O13: 0.9466 | R13: PRBQ1 | T13: 53.592314 | U13: 53.592314 | V13: 0.030230166
B14: 0.5 | C14: 0.001 | D14: 8 | E14: 0.4901848 | F14: 0.1958125 | G14: 0.99428571 | H14: 0.3270627 | I14: 0.08963537 | J14: 0.011287153 | K14: 0.02857143 | L14: 0.01622444 | N14: Accuracy | O14: 0.827 | R14: PRBQ29 | T14: 49.749373 | U14: 49.749373 | V14: 0.017303897
B15: 1 | C15: 0.001 | D15: 2 | E15: 0.4873355 | F15: 1 | G15: 0.005714286 | H15: 0.25 | I15: 0.0920033 | J15: NA | K15: 0.02857143 | L15: NA | N15: F-Score | O15: 0.6444 | R15: SCQ3 | T15: 49.081036 | U15: 49.081036 | V15: 0.036759102
B16: 1 | C16: 0.001 | D16: 4 | E16: 0.4953413 | F16: 0.4859836 | G16: 0.74357143 | H16: 0.5802372 | I16: 0.09102472 | J16: 0.093272716 | K16: 0.16631127 | L16: 0.10400513 | N16: MCC | O16: 0.5554 | R16: PRBQ14 | T16: 40.643275 | U16: 40.643275 | V16: 0.022112501
B17: 1 | C17: 0.001 | D17: 8 | E17: 0.4880636 | F17: 0.2479801 | G17: 0.91714286 | H17: 0.3890893 | I17: 0.08690982 | J17: 0.035129454 | K17: 0.10588046 | L17: 0.0472755 | N17: Balanced Accuracy | O17: 0.8189 | R17: PRBQ23 | T17: 41.645781 | U17: 41.645781 | V17: 0.021004404
B18: 2 | C18: 0.001 | D18: 2 | E18: 0.4864703 | F18: 0.8055556 | G18: 0.15214286 | H18: 0.3666667 | I18: 0.0953209 | J18: 0.33455658 | K18: 0.1351256 | L18: 0.11114814 | R18: Cig7 | V18: 0.023749684
B19: 2 | C19: 0.001 | D19: 4 | E19: 0.4720402 | F19: 0.4590173 | G19: 0.70928571 | H19: 0.5496101 | I19: 0.08301471 | J19: 0.094776418 | K19: 0.16378677 | L19: 0.10339336 | N19: Confusion Matrix: Testing Data | R19: Cig7_X2 | T19: 55.096074 | U19: 55.096074
B20: 2 | C20: 0.001 | D20: 8 | E20: 0.4755493 | F20: 0.3412449 | G20: 0.84428571 | H20: 0.4833253 | I20: 0.0942806 | J20: 0.047533148 | K20: 0.12028965 | L20: 0.05654702 | N20: SVM-WR | O20: Reference Yes | P20: Reference No | R20: ContemplationStatus | V20: 0.037769372
B21: 3 | C21: 0.001 | D21: 2 | E21: 0.4822306 | F21: 0.7019841 | G21: 0.29142857 | H21: 0.4203367 | I21: 0.09063892 | J21: 0.25689512 | K21: 0.18135626 | L21: 0.16905172 | N21: Predict Yes | O21: 3 | P21: 7 | R21: ContemplationStatus_X2 | T21: 44.402673 | U21: 44.402673
B22: 3 | C22: 0.001 | D22: 4 | E22: 0.4760552 | F22: 0.4611667 | G22: 0.70571429 | H22: 0.5480778 | I22: 0.0854777 | J22: 0.090029522 | K22: 0.16768291 | L22: 0.09712833 | N22: Predict No | O22: 6 | P22: 30 | R22: ContemplationStatus_X3 | T22: 38.93066 | U22: 38.93066
B23: 3 | C23: 0.001 | D23: 8 | E23: 0.4602519 | F23: 0.3624249 | G23: 0.80428571 | H23: 0.4946025 | I23: 0.0903734 | J23: 0.070244939 | K23: 0.1768879 | L23: 0.08568908 | R23: ContemplationStatus_X4 | T23: 24.519632 | U23: 24.519632
B24: 4 | C24: 0.001 | D24: 2 | E24: 0.4779083 | F24: 0.6659151 | G24: 0.38857143 | H24: 0.4937728 | I24: 0.09297773 | J24: 0.23483121 | K24: 0.21343332 | L24: 0.14808912 | N24: Testing Performance | R24: ContemplationStatus_X5 | T24: 38.053467 | U24: 38.053467
B25: 4 | C25: 0.001 | D25: 4 | E25: 0.4840358 | F25: 0.4696864 | G25: 0.70071429 | H25: 0.5536999 | I25: 0.08883279 | J25: 0.10397715 | K25: 0.15739631 | L25: 0.10195388 | N25: Sensitivity | O25: 0.33333 | R25: EducationRc | V25: 0.041026843
B26: 4 | C26: 0.001 | D26: 8 | E26: 0.454881 | F26: 0.3723326 | G26: 0.79928571 | H26: 0.5025378 | I26: 0.08665428 | J26: 0.068306223 | K26: 0.17284571 | L26: 0.08098998 | N26: Specificity | O26: 0.81081 | R26: EducationRc_X2 | T26: 2.29741 | U26: 2.29741
B27: 5 | C27: 0.001 | D27: 2 | E27: 0.4719719 | F27: 0.6102273 | G27: 0.43214286 | H27: 0.5162621 | I27: 0.08227683 | J27: 0.20188216 | K27: 0.2107849 | L27: 0.11812437 | N27: Precision (PPV) | O27: 0.3 | R27: EducationRc_X3 | T27: 20.676692 | U27: 20.676692
B28: 5 | C28: 0.001 | D28: 4 | E28: 0.4810188 | F28: 0.4736497 | G28: 0.70071429 | H28: 0.5552206 | I28: 0.08602706 | J28: 0.10927846 | K28: 0.15739631 | L28: 0.09987417 | N28: Negative Predictive Value (NPV) | O28: 0.83333 | R28: EducationRc_X4 | T28: 34.544695 | U28: 34.544695
B29: 5 | C29: 0.001 | D29: 8 | E29: 0.4439639 | F29: 0.3761961 | G29: 0.79357143 | H29: 0.5052025 | I29: 0.08765976 | J29: 0.072645501 | K29: 0.16823349 | L29: 0.08469933 | N29: Accuracy | O29: 0.7174 | R29: EducationRc_X5 | T29: 3.258145 | U29: 3.258145
B30: 6 | C30: 0.001 | D30: 2 | E30: 0.4636363 | F30: 0.6179683 | G30: 0.455 | H30: 0.5147614 | I30: 0.08826074 | J30: 0.21673619 | K30: 0.19650431 | L30: 0.12335924 | N30: F-Score | O30: 0.3158 | R30: EducationRc_X6 | T30: 0 | U30: 0
B31: 6 | C31: 0.001 | D31: 4 | E31: 0.4748163 | F31: 0.4752959 | G31: 0.68928571 | H31: 0.5509582 | I31: 0.08634329 | J31: 0.10469814 | K31: 0.16406883 | L31: 0.09909672 | N31: MCC | O31: 0.1386 | R31: SoC2BRc | V31: 0.028647283
B32: 6 | C32: 0.001 | D32: 8 | E32: 0.4391164 | F32: 0.3769645 | G32: 0.77642857 | H32: 0.5012575 | I32: 0.07985033 | J32: 0.074810307 | K32: 0.16302245 | L32: 0.0811357 | N32: Balanced Accuracy | O32: 0.57207 | R32: SoC2BRc_X2 | T32: 60.192147 | U32: 60.192147
B33: 7 | C33: 0.001 | D33: 2 | E33: 0.4603652 | F33: 0.6048341 | G33: 0.46642857 | H33: 0.5156268 | I33: 0.08744475 | J33: 0.21925629 | K33: 0.19012617 | L33: 0.11726309 | R33: SoC5BRc | V33: 0.016503694
B34: 7 | C34: 0.001 | D34: 4 | E34: 0.4715999 | F34: 0.4767273 | G34: 0.68928571 | H34: 0.5514692 | I34: 0.08879623 | J34: 0.11468203 | K34: 0.17412622 | L34: 0.11337187 | N34: AUC by Repeated Resample | R34: SoC5BRc_X2 | T34: 54.845447 | U34: 54.845447
B35: 7 | C35: 0.001 | D35: 8 | E35: 0.4315279 | F35: 0.3773668 | G35: 0.765 | H35: 0.4992754 | I35: 0.08496478 | J35: 0.068205806 | K35: 0.15658383 | L35: 0.07437222 | N35: Resample | O35: AUC | R35: SSEQ8BRc | V35: 0.018960908
B36: 8 | C36: 0.001 | D36: 2 | E36: 0.4545905 | F36: 0.5934603 | G36: 0.49357143 | H36: 0.5321576 | I36: 0.08896833 | J36: 0.19976083 | K36: 0.19642045 | L36: 0.11322098 | N36: Rep1 | O36: 0.396727 | R36: SSEQ8BRc_X2 | T36: 33.375104 | U36: 33.375104
B37: 8 | C37: 0.001 | D37: 4 | E37: 0.4685847 | F37: 0.4814698 | G37: 0.67857143 | H37: 0.5474175 | I37: 0.08035467 | J37: 0.1196152 | K37: 0.1754186 | L37: 0.1045581 | N37: Rep2 | O37: 0.3802486 | R37: SSEQ8BRc_X3 | T37: 15.288221 | U37: 15.288221
B38: 8 | C38: 0.001 | D38: 8 | E38: 0.4288669 | F38: 0.3710868 | G38: 0.74928571 | H38: 0.4903563 | I38: 0.0820486 | J38: 0.055924136 | K38: 0.16133149 | L38: 0.06763724 | N38: Rep3 | O38: 0.4005824 | R38: SSEQ8BRc_X4 | T38: 47.159566 | U38: 47.159566
B39: 9 | C39: 0.001 | D39: 2 | E39: 0.4519412 | F39: 0.5702441 | G39: 0.495 | H39: 0.5277465 | I39: 0.08654558 | J39: 0.19019671 | K39: 0.20687329 | L39: 0.12168297 | N39: Rep4 | O39: 0.3976375 | R39: SSS17 | V39: 0.029548449
B40: 9 | C40: 0.001 | D40: 4 | E40: 0.4686792 | F40: 0.4771164 | G40: 0.68428571 | H40: 0.5473734 | I40: 0.08084106 | J40: 0.11148167 | K40: 0.17410485 | L40: 0.10077578 | N40: Rep5 | O40: 0.41939 | R40: SSS17_X1 | T40: 47.577277 | U40: 47.577277
B41: 9 | C41: 0.001 | D41: 8 | E41: 0.4161999 | F41: 0.3738681 | G41: 0.74928571 | H41: 0.4931947 | I41: 0.07840949 | J41: 0.058457546 | K41: 0.16133149 | L41: 0.07109023 | R41: SSEQ6BRc | V41: -0.0007397804
B42: 10 | C42: 0.001 | D42: 2 | E42: 0.4575931 | F42: 0.5750854 | G42: 0.50071429 | H42: 0.5285161 | I42: 0.07732663 | J42: 0.20285309 | K42: 0.20693493 | L42: 0.11180011 | N42: Hyperparameters | P42: Support Vectors | R42: SSEQ6BRc_X2 | T42: 42.230576 | U42: 42.230576
...

Sheet SVM Data
B2: Support Vector Classifier
B4: Testing | C4: SVM-L | D4: TPR | E4: =IF('SVM Linear'!M25="","",'SVM Linear'!M25) -> 0.22222
D5: TNR | E5: =IF('SVM Linear'!M26="","",'SVM Linear'!M26) -> 1
D6: PPV | E6: =IF('SVM Linear'!M27="","",'SVM Linear'!M27) -> 1
D7: NPV | E7: =IF('SVM Linear'!M28="","",'SVM Linear'!M28) -> 0.84091
D8: ACC | E8: =IF('SVM Linear'!M29="","",'SVM Linear'!M29) -> 0.8478
D9: F1 | E9: =IF('SVM Linear'!M30="","",'SVM Linear'!M30) -> 0.3636
D10: MCC | E10: =IF('SVM Linear'!M31="","",'SVM Linear'!M31) -> 0.4323
D11: BACC | E11: =IF('SVM Linear'!M32="","",'SVM Linear'!M32) -> 0.61111
C12: SVM-P | D12: TPR | E12: =IF('SVM Polynomial'!O25="","",'SVM Polynomial'!O25) -> 0.1111
D13: TNR | E13: =IF('SVM Polynomial'!O26="","",'SVM Polynomial'!O26) -> 1
D14: PPV | E14: =IF('SVM Polynomial'!O27="","",'SVM Polynomial'!O27) -> 1
D15: NPV | E15: =IF('SVM Polynomial'!O28="","",'SVM Polynomial'!O28) -> 0.8222
D16: ACC | E16: =IF('SVM Polynomial'!O29="","",'SVM Polynomial'!O29) -> 0.8261
D17: F1 | E17: =IF('SVM Polynomial'!O30="","",'SVM Polynomial'!O30) -> 0.2
D18: MCC | E18: =IF('SVM Polynomial'!O31="","",'SVM Polynomial'!O31) -> 0.30225
D19: BACC | E19: =IF('SVM Polynomial'!O32="","",'SVM Polynomial'!O32) -> 0.5556
C20: SVM-R | D20: TPR | E20: =IF('SVM Radial'!N25="","",'SVM Radial'!N25) -> 0.1111
D21: TNR | E21: =IF('SVM Radial'!N26="","",'SVM Radial'!N26) -> 1
D22: PPV | E22: =IF('SVM Radial'!N27="","",'SVM Radial'!N27) -> 1
D23: NPV | E23: =IF('SVM Radial'!N28="","",'SVM Radial'!N28) -> 0.8222
D24: ACC | E24: =IF('SVM Radial'!N29="","",'SVM Radial'!N29) -> 0.8261
D25: F1 | E25: =IF('SVM Radial'!N30="","",'SVM Radial'!N30) -> 0.2
D26: MCC | E26: =IF('SVM Radial'!N31="","",'SVM Radial'!N31) -> 0.30225
D27: BACC | E27: =IF('SVM Radial'!N32="","",'SVM Radial'!N32) -> 0.5556
C28: SVM-RW4 | D28: TPR | E28: =IF('SVM Weighted Radial'!O25="","",'SVM Weighted Radial'!O25) -> 0.33333
D29: TNR | E29: =IF('SVM Weighted Radial'!O26="","",'SVM Weighted Radial'!O26) -> 0.81081
D30: PPV | E30: =IF('SVM Weighted Radial'!O27="","",'SVM Weighted Radial'!O27) -> 0.3
D31: NPV | E31: =IF('SVM Weighted Radial'!O28="","",'SVM Weighted Radial'!O28) -> 0.83333
D32: ACC | E32: =IF('SVM Weighted Radial'!O29="","",'SVM Weighted Radial'!O29) -> 0.7174
D33: F1 | E33: =IF('SVM Weighted Radial'!O30="","",'SVM Weighted Radial'!O30) -> 0.3158
D34: MCC | E34: =IF('SVM Weighted Radial'!O31="","",'SVM Weighted Radial'!O31) -> 0.1386
D35: BACC | E35: =IF('SVM Weighted Radial'!O32="","",'SVM Weighted Radial'!O32) -> 0.57207
B36: Training | C36: SVM-L | D36: TPR | E36: =IF('SVM Linear'!M10="","",'SVM Linear'!M10) -> 0.41667
D37: TNR | E37: =IF('SVM Linear'!M11="","",'SVM Linear'!M11) -> 0.97987
D38: PPV | E38: =IF('SVM Linear'!M12="","",'SVM Linear'!M12) -> 0.83333
D39: NPV | E39: =IF('SVM Linear'!M13="","",'SVM Linear'!M13) -> 0.87425
D40: ACC | E40: =IF('SVM Linear'!M14="","",'SVM Linear'!M14) -> 0.8703
D41: F1 | E41: =IF('SVM Linear'!M15="","",'SVM Linear'!M15) -> 0.5556
D42: MCC | E42: =IF('SVM Linear'!M16="","",'SVM Linear'!M16) -> 0.5297
...

Sheet Random Forest>

Sheet RF
B2: Random Forest
B4: Average Repeated 5-Fold Cross-Validation Training Performance | M4: Confusion Matrix: Training Data* | Q4: Variable | R4: Variable Label | S4: Caret (AUROC) | U4: Manual (AUPRC)
B5: mtry | C5: ntree | D5: AUPRC2 | E5: Precision | F5: Recall | G5: F | H5: AUPRC SD | I5: Precision SD | J5: Recall SD | K5: F SD | M5: RF | N5: Reference Yes | O5: Reference No | S5: X1 | T5: X2 | W5: Manual AUPRC value represents amount drop in AUPRC when variable is left out.
B6: 2 | C6: 100 | D6: 0.4802748 | E6: 0.8621212 | F6: 0.2228571 | G6: 0.3778926 | H6: 0.10596027 | I6: 0.1971478 | J6: 0.13639787 | K6: 0.13400114 | M6: Predict Yes | N6: 36 | O6: 0 | Q6: Cig9Rc | S6: 83.853211 | T6: 83.853211 | U6: 0.0007610826
B7: 2 | C7: 300 | D7: 0.4917509 | E7: 0.9206349 | F7: 0.2014286 | G7: 0.3714286 | H7: 0.09845301 | I7: 0.1717479 | J7: 0.12355887 | K7: 0.12105868 | M7: Predict No | N7: 0 | O7: 149 | Q7: PRBQ18 | S7: 42.614679 | T7: 42.614679 | U7: 0
B8: 2 | C8: 500 | D8: 0.5085285 | E8: 0.8791667 | F8: 0.1907143 | G8: 0.3669949 | H8: 0.09798763 | I8: 0.1977117 | J8: 0.12141106 | K8: 0.10490411 | Q8: SCQ14 | S8: 51.605505 | T8: 51.605505 | U8: 0.015281154
B9: 2 | C9: 700 | D9: 0.4951082 | E9: 0.9484127 | F9: 0.1957143 | G9: 0.3648629 | H9: 0.09647248 | I9: 0.1355959 | J9: 0.1156678 | K9: 0.10495778 | M9: Training Performance | O9: *Model re-fit to full data. | Q9: SCQ34 | S9: 50.366973 | T9: 50.366973 | U9: 0
B10: 2 | C10: 900 | D10: 0.4964718 | E10: 0.9242424 | F10: 0.19 | G10: 0.3429293 | H10: 0.09173647 | I10: 0.1684608 | J10: 0.09860313 | K10: 0.09893884 | M10: Sensitivity | N10: 1 | Q10: PRBQ2 | S10: 47.155963 | T10: 47.155963 | U10: 0
B11: 2 | C11: 1100 | D11: 0.4951312 | E11: 0.9365079 | F11: 0.1785714 | G11: 0.3402116 | H11: 0.0923291 | I11: 0.1622429 | J11: 0.10348416 | K11: 0.10053721 | M11: Specificity | N11: 1 | Q11: PRBQ17 | S11: 19.541284 | T11: 19.541284 | U11: 0
B12: 2 | C12: 1300 | D12: 0.4958776 | E12: 0.9246032 | F12: 0.1957143 | G12: 0.3635402 | H12: 0.09823413 | I12: 0.1664681 | J12: 0.1156678 | K12: 0.10663931 | M12: Precision (PPV) | N12: 1 | Q12: SCQ19 | S12: 31.330275 | T12: 31.330275 | U12: 0
B13: 3 | C13: 100 | D13: 0.4591057 | E13: 0.76875 | F13: 0.2471429 | G13: 0.3855292 | H13: 0.10757308 | I13: 0.2704582 | J13: 0.12655075 | K13: 0.12232621 | M13: Negative Predictive Value (NPV) | N13: 1 | Q13: PRBQ1 | S13: 32.889908 | T13: 32.889908 | U13: 0.0063156947
B14: 3 | C14: 300 | D14: 0.4748039 | E14: 0.7971014 | F14: 0.2228571 | G14: 0.3763545 | H14: 0.08971422 | I14: 0.2704118 | J14: 0.10863544 | K14: 0.09293055 | M14: Accuracy | N14: 1 | Q14: PRBQ29 | S14: 28.669725 | T14: 28.669725 | U14: 0
B15: 3 | C15: 500 | D15: 0.4915268 | E15: 0.8644928 | F15: 0.2514286 | G15: 0.4179522 | H15: 0.10184706 | I15: 0.2524778 | J15: 0.15506952 | K15: 0.14728608 | M15: F-Score | N15: 1 | Q15: SCQ3 | S15: 27.93578 | T15: 27.93578 | U15: 0.0007610826
B16: 3 | C16: 700 | D16: 0.4860469 | E16: 0.8478261 | F16: 0.2407143 | G16: 0.3815429 | H16: 0.09912762 | I16: 0.2051302 | J16: 0.13502724 | K16: 0.12932749 | M16: MCC | N16: 1 | Q16: PRBQ14 | S16: 18.669725 | T16: 18.669725 | U16: 0.01417647
B17: 3 | C17: 900 | D17: 0.4796466 | E17: 0.8825758 | F17: 0.23 | G17: 0.3912075 | H17: 0.10131368 | I17: 0.190132 | J17: 0.12321429 | K17: 0.11588541 | M17: Balanced Accuracy | N17: 1 | Q17: PRBQ23 | S17: 19.770642 | T17: 19.770642 | U17: 0
B18: 3 | C18: 1100 | D18: 0.4868973 | E18: 0.875 | F18: 0.235 | G18: 0.3921594 | H18: 0.09437474 | I18: 0.202089 | J18: 0.14076594 | K18: 0.12896687 | Q18: Cig7 | S18: 34.541284 | T18: 34.541284 | U18: 0
B19: 3 | C19: 1300 | D19: 0.4884156 | E19: 0.8905797 | F19: 0.24 | G19: 0.387242 | H19: 0.09505497 | I19: 0.1795636 | J19: 0.12763798 | K19: 0.11836898 | M19: Confusion Matrix: Testing Data | Q19: ContemplationStatus | S19: 100 | T19: 100 | U19: 0.03491909
B20: 4 | C20: 100 | D20: 0.4618831 | E20: 0.692 | F20: 0.3014286 | G20: 0.4360343 | H20: 0.09300198 | I20: 0.2922264 | J20: 0.15849325 | K20: 0.13499321 | M20: RF | N20: Reference Yes | O20: Reference No | Q20: EducationRc | S20: 0 | T20: 0 | U20: 0
B21: 4 | C21: 300 | D21: 0.4737404 | E21: 0.7798611 | F21: 0.2642857 | G21: 0.3838141 | H21: 0.09153076 | I21: 0.2050674 | J21: 0.14154907 | K21: 0.14377135 | M21: Predict Yes | N21: 2 | O21: 1 | Q21: SoC2BRc | S21: 40.137615 | T21: 40.137615 | U21: 0
B22: 4 | C22: 500 | D22: 0.483299 | E22: 0.7704969 | F22: 0.2642857 | G22: 0.398626 | H22: 0.09815687 | I22: 0.2239174 | J22: 0.14013402 | K22: 0.1289195 | M22: Predict No | N22: 7 | O22: 36 | Q22: SoC5BRc | S22: 34.266055 | T22: 34.266055 | U22: 0
B23: 4 | C23: 700 | D23: 0.4805389 | E23: 0.8238095 | F23: 0.2571429 | G23: 0.3964929 | H23: 0.10733192 | I23: 0.2388818 | J23: 0.14788403 | K23: 0.13706298 | Q23: SSEQ8BRc | S23: 20.779816 | T23: 20.779816 | U23: 0
B24: 4 | C24: 900 | D24: 0.4747463 | E24: 0.766 | F24: 0.2742857 | G24: 0.3984185 | H24: 0.10437963 | I24: 0.2725259 | J24: 0.13539671 | K24: 0.13719707 | M24: Testing Performance | Q24: SSS17 | S24: 26.284404 | T24: 26.284404 | U24: 0
B25: 4 | C25: 1100 | D25: 0.4746197 | E25: 0.7614907 | F25: 0.2921429 | G25: 0.4245274 | H25: 0.10587889 | I25: 0.2212698 | J25: 0.1659914 | K25: 0.14278492 | M25: Sensitivity | N25: 0.22222 | Q25: SSEQ6BRc | S25: 0.2293578 | T25: 0.2293578 | U25: 0.002490379
B26: 4 | C26: 1300 | D26: 0.4798461 | E26: 0.7645833 | F26: 0.2742857 | G26: 0.3967981 | H26: 0.09927207 | I26: 0.2285383 | J26: 0.14153781 | K26: 0.14345583 | M26: Specificity | N26: 0.97297
B27: 5 | C27: 100 | D27: 0.4676054 | E27: 0.7640873 | F27: 0.2907143 | G27: 0.4169671 | H27: 0.08405251 | I27: 0.2246481 | J27: 0.11839703 | K27: 0.10524798 | M27: Precision (PPV) | N27: 0.66667
B28: 5 | C28: 300 | D28: 0.4605555 | E28: 0.73 | F28: 0.285 | G28: 0.4008709 | H28: 0.10135251 | I28: 0.2729299 | J28: 0.15715977 | K28: 0.14856236 | M28: Negative Predictive Value (NPV) | N28: 0.83721
B29: 5 | C29: 500 | D29: 0.4683142 | E29: 0.7759921 | F29: 0.2914286 | G29: 0.4055391 | H29: 0.11103414 | I29: 0.239866 | J29: 0.17660525 | K29: 0.16509643 | M29: Accuracy | N29: 0.8261 | Q29: AUPRC by Repeated Resample
B30: 5 | C30: 700 | D30: 0.4702993 | E30: 0.7065972 | F30: 0.285 | G30: 0.3965278 | H30: 0.10533202 | I30: 0.2347393 | J30: 0.1516526 | K30: 0.143769 | M30: F-Score | N30: 0.3333 | Q30: Resample | R30: AUPRC
B31: 5 | C31: 900 | D31: 0.4738227 | E31: 0.7339048 | F31: 0.2857143 | G31: 0.4022253 | H31: 0.10309899 | I31: 0.2713836 | J31: 0.16423071 | K31: 0.1554856 | M31: MCC | N31: 0.3136 | Q31: Rep1 | R31: 0.5686608
B32: 5 | C32: 1100 | D32: 0.4668026 | E32: 0.7366667 | F32: 0.2857143 | G32: 0.4017304 | H32: 0.10132013 | I32: 0.2631715 | J32: 0.15896869 | K32: 0.14719342 | M32: Balanced Accuracy | N32: 0.5976 | Q32: Rep2 | R32: 0.5111879
B33: 5 | C33: 1300 | D33: 0.4645801 | E33: 0.7430556 | F33: 0.2964286 | G33: 0.4070464 | H33: 0.10147264 | I33: 0.225699 | J33: 0.1771521 | K33: 0.15689348 | Q33: Rep3 | R33: 0.5619789
B34: 6 | C34: 100 | D34: 0.4516632 | E34: 0.672381 | F34: 0.32 | G34: 0.4115444 | H34: 0.10716414 | I34: 0.2524553 | J34: 0.18041607 | K34: 0.13544363 | M34: Confusion Matrix: OOB (Training) Data* | Q34: Rep4 | R34: 0.5188309
B35: 6 | C35: 300 | D35: 0.4517043 | E35: 0.6888889 | F35: 0.285 | G35: 0.3871487 | H35: 0.10315575 | I35: 0.2430516 | J35: 0.17378098 | K35: 0.14777613 | M35: RF | N35: Reference Yes | O35: Reference No | Q35: Rep5 | R35: 0.5666192
B36: 6 | C36: 500 | D36: 0.4587113 | E36: 0.6946429 | F36: 0.2971429 | G36: 0.3995192 | H36: 0.10540338 | I36: 0.2260518 | J36: 0.18231784 | K36: 0.15549446 | M36: Predict Yes | N36: 12 | O36: 24
B37: 6 | C37: 700 | D37: 0.4566461 | E37: 0.6864583 | F37: 0.2971429 | G37: 0.401308 | H37: 0.09476664 | I37: 0.2117732 | J37: 0.15854019 | K37: 0.13788685 | M37: Predict No | N37: 7 | O37: 142 | Q37: Hyperparameters
B38: 6 | C38: 900 | D38: 0.463154 | E38: 0.6966667 | F38: 0.3078571 | G38: 0.4103584 | H38: 0.10839835 | I38: 0.2679383 | J38: 0.17604462 | K38: 0.14524686 | Q38: mtry = 10
B39: 6 | C39: 1100 | D39: 0.4665099 | E39: 0.6978095 | F39: 0.3071429 | G39: 0.4185305 | H39: 0.10864772 | I39: 0.2727983 | J39: 0.17450732 | K39: 0.15501555 | M39: OOB Error Estimates* | O39: *From re-fit to full Training (i.e., not Tuning) | Q39: ntree = 700
B40: 6 | C40: 1300 | D40: 0.4668107 | E40: 0.7309524 | F40: 0.2907143 | G40: 0.3995065 | H40: 0.11262804 | I40: 0.2372646 | J40: 0.15976239 | K40: 0.14937253 | M40: OOB = 16.76%
B41: 7 | C41: 100 | D41: 0.4365839 | E41: 0.6638571 | F41: 0.2964286 | G41: 0.3990556 | H41: 0.10039641 | I41: 0.2583376 | J41: 0.1525715 | K41: 0.12583885 | M41: X1 = 0.66666667
B42: 7 | C42: 300 | D42: 0.4493403 | E42: 0.672371 | F42: 0.2964286 | G42: 0.3956187 | H42: 0.10947018 | I42: 0.2537049 | J42: 0.15804664 | K42: 0.12220992 | M42: X2 = 0.04697987
...

Sheet RF-W4
B2: Random Forest: Weight 4
B4: Average Repeated 5-Fold Cross-Validation Training Performance | M4: Confusion Matrix: Training Data* | Q4: Variable | R4: Variable Label | S4: Caret (AUROC) | U4: Manual (AUPRC)
B5: mtry | C5: ntree | D5: AUPRC2 | E5: Precision | F5: Recall | G5: F | H5: AUPRC SD | I5: Precision SD | J5: Recall SD | K5: F SD | M5: RF-W4 | N5: Reference Yes | O5: Reference No | S5: X1 | T5: X2
B6: 2 | C6: 100 | D6: 0.4219685 | E6: 0.8921569 | F6: 0.1392857 | G6: 0.3267974 | H6: 0.09479071 | I6: 0.2036232 | J6: 0.115152 | K6: 0.10523041 | M6: Predict Yes | N6: 36 | O6: 0 | Q6: Cig9Rc | S6: 83.853211 | T6: 83.853211 | U6: 0.0014815693
B7: 2 | C7: 300 | D7: 0.4391201 | E7: 0.9166667 | F7: 0.1392857 | G7: 0.3145062 | H7: 0.09309551 | I7: 0.1917412 | J7: 0.1056443 | K7: 0.09768822 | M7: Predict No | N7: 0 | O7: 149 | Q7: PRBQ18 | S7: 42.614679 | T7: 42.614679 | U7: 0
B8: 2 | C8: 500 | D8: 0.4395088 | E8: 0.9210526 | F8: 0.135 | G8: 0.3089506 | H8: 0.09818214 | I8: 0.2507299 | J8: 0.1050237 | K8: 0.09951113 | Q8: SCQ14 | S8: 51.605505 | T8: 51.605505 | U8: 0.0064032459
B9: 2 | C9: 700 | D9: 0.4405376 | E9: 0.8333333 | F9: 0.14 | G9: 0.3149551 | H9: 0.09227385 | I9: 0.3289181 | J9: 0.1074747 | K9: 0.09908597 | M9: Training Performance | O9: *Model re-fit to full data. | Q9: SCQ34 | S9: 50.366973 | T9: 50.366973 | U9: 0
B10: 2 | C10: 900 | D10: 0.4501976 | E10: 0.9736842 | F10: 0.15 | G10: 0.3230994 | H10: 0.09695916 | I10: 0.1147079 | J10: 0.1055184 | K10: 0.09820514 | M10: Sensitivity | N10: 1 | Q10: PRBQ2 | S10: 47.155963 | T10: 47.155963 | U10: 0
